Workbook

Sheet J1-Page1
A1: Plant Name: | C1: Wentzville | E1: STANDARD TASK SHEET | AB1: Available Op Time | AC1: Frequency | AD1: Shift Conditional | AF1: SPQRCE
A2: Department / Area: | F2: Available Operating Time: | I2: Prepared By: | AB2: 440 minutes (8 hours) | AC2: D | AD2: Y | AF2: S
A3: Trim - IP GLASS | F3: 440 minutes (8 hours) | I3: R. Woodson | AB3: 456 minutes (8 hours) | AC3: W | AD3: N | AF3: P
A4: Operation Name: | F4: Team: | I4: Page: | J4: Date: | AB4: 516 minutes(9 hours) | AC4: M | AF4: Q
A5: Team Leader | F5: J1 | I5: 1 of 2 | J5: 46114 | AB5: 576 minutes (10 hours) | AC5: Y | AF5: R
A6: STS Base Line Knowledge/Training: | AF6: C
AF7: E
A8: SAFETY | B8: All Required Safety Training (inc. Haz Material) | F8: QUALITY | G8: Process Control Plans | J8: COST | K8: Point Of Use, Spare Parts and Warranty
B9: High Risk TIS's/ Take 2 | G9: Quality Alerts | K9: COMMWIP - Waste Elimination
B10: Safety Playbook and Safety Policy | G10: Product Quality Standards | K10: Basic Ind. Material/Purchasing/SAP
B11: Emergency Response Process | G11: BIQ Process: Level III/IV | K11: Scrap Process
B12: SOT, SIR, ESCP, SOP, PPE, Ergonomics | G12: Problem Solving/Continuous Improvement
B13: Pre Task Planning/ Pre-Op card process | G13: Understanding PFMEA and MFMEA
A14: PEOPLE | B14: Computer Skills-E-mail, Microsoft Office, etc. | G14: GSIP | J14: ENVIRONMENTAL | K14: Understand E Requirements of the area
B15: TM/TL Evaluation Process | G15: Shop Floor Quality Systems - FBFF | K15: Work Place Organization (5-S)
B16: 4 Quarter Certified in all Team Jobs | G16: ISO | K16: Environmental Aspects / TISs
B17: Suggestions | F17: RESP. | G17: PM&C
B18: JIT Training & Flexibility Chart Training | G18: TIP (OEE and Constraints Management)
B19: GMS Training | G19: Maximo (CMMS)
B20: Layered Audits | G20: Andon and Plant Escalation Process
B21: Leading Effective Meetings | G21: Material Delivery System
B22: Team Concept, TM & TL R&Rs | G22: Total Productive Maintenance (TPM) | J22: SPQRCE | K22: JES/SOS/TIS (Safety/People/Responsiveness)
B23: TL STS and TISs | K23: BPD and Level 5 (SPQRCE)
B24: Plant Recognition Process | K24: Standardized Work (JES/SOS/TIS)
B25: Coaching Skills to help TMs improve
B26: Complete Proficiency Check Lists-3/4 Harvey
A28: SPQRCE | B28: # | C28: Task: | H28: TIS: | I28: Notes: | M28: Task Cycle Time: (Min.) | N28: Frequency: (Time) I (D=Day, W=Week, M=Month, Y=Year) | P28: Shift | S28: Total Cycle Time: (Daily) SHIFT
P29: 1 | Q29: 2 | R29: 3 | S29: 1 | T29: 2 | U29: 3
A30: S | B30: 1 | C30: Confirm Team Members are Wearing PPE. | H30: TIS-00-0018 | M30: 5 | N30: 1 | O30: D | P30: Y | Q30: Y | R30: Y | S30: =IF(P30="Y",IF(O30="D",M30*N30,IF(O30="W",M30*(N30/5),IF(O30="M",M30*(N30/22),IF(O30="Y",M30*(N30/(22*12)), "")))),0) -> 5 | T30: =IF(Q30="Y",IF(O30="D",M30*N30,IF(O30="W",M30*(N30/5),IF(O30="M",M30*(N30/22),IF(O30="Y",M30*(N30/(22*12)), "")))),0) -> 5 | U30: =IF(R30="Y",IF(O30="D",M30*N30,IF(O30="W",M30*(N30/5),IF(O30="M",M30*(N30/22),IF(O30="Y",M30*(N30/(22*12)), "")))),0) -> 5
A31: S | B31: 2 | C31: Perform Safety Observation Tour (SOT) | I31: Be proactive - not reactive | M31: 20 | N31: 1 | O31: W | P31: Y | Q31: Y | R31: Y | S31: =IF(P31="Y",IF(O31="D",M31*N31,IF(O31="W",M31*(N31/5),IF(O31="M",M31*(N31/22),IF(O31="Y",M31*(N31/(22*12)), "")))),0) -> 4 | T31: =IF(Q31="Y",IF(O31="D",M31*N31,IF(O31="W",M31*(N31/5),IF(O31="M",M31*(N31/22),IF(O31="Y",M31*(N31/(22*12)), "")))),0) -> 4 | U31: =IF(R31="Y",IF(O31="D",M31*N31,IF(O31="W",M31*(N31/5),IF(O31="M",M31*(N31/22),IF(O31="Y",M31*(N31/(22*12)), "")))),0) -> 4
A32: P | B32: 3 | C32: Check email. | I32: If you cannot log in, ESCALATE! | M32: 5 | N32: 1 | O32: D | P32: Y | Q32: Y | R32: Y | S32: =IF(P32="Y",IF(O32="D",M32*N32,IF(O32="W",M32*(N32/5),IF(O32="M",M32*(N32/22),IF(O32="Y",M32*(N32/(22*12)), "")))),0) -> 5 | T32: =IF(Q32="Y",IF(O32="D",M32*N32,IF(O32="W",M32*(N32/5),IF(O32="M",M32*(N32/22),IF(O32="Y",M32*(N32/(22*12)), "")))),0) -> 5 | U32: =IF(R32="Y",IF(O32="D",M32*N32,IF(O32="W",M32*(N32/5),IF(O32="M",M32*(N32/22),IF(O32="Y",M32*(N32/(22*12)), "")))),0) -> 5
A33: P | B33: 4 | C33: Engage in BPD-Daily TL/GL Huddle | H33: TIS-00-0024 | I33: Update BPD daily @ Huddle | M33: 15 | N33: 1 | O33: D | P33: Y | Q33: Y | R33: Y | S33: =IF(P33="Y",IF(O33="D",M33*N33,IF(O33="W",M33*(N33/5),IF(O33="M",M33*(N33/22),IF(O33="Y",M33*(N33/(22*12)), "")))),0) -> 15 | T33: =IF(Q33="Y",IF(O33="D",M33*N33,IF(O33="W",M33*(N33/5),IF(O33="M",M33*(N33/22),IF(O33="Y",M33*(N33/(22*12)), "")))),0) -> 15 | U33: =IF(R33="Y",IF(O33="D",M33*N33,IF(O33="W",M33*(N33/5),IF(O33="M",M33*(N33/22),IF(O33="Y",M33*(N33/(22*12)), "")))),0) -> 15
A34: P | B34: 5 | C34: Lead/engage TMs in problem solving for CI, CM or PPS | I34: Escalate as required. | M34: 10 | N34: 1 | O34: D | P34: Y | Q34: Y | R34: Y | S34: =IF(P34="Y",IF(O34="D",M34*N34,IF(O34="W",M34*(N34/5),IF(O34="M",M34*(N34/22),IF(O34="Y",M34*(N34/(22*12)), "")))),0) -> 10 | T34: =IF(Q34="Y",IF(O34="D",M34*N34,IF(O34="W",M34*(N34/5),IF(O34="M",M34*(N34/22),IF(O34="Y",M34*(N34/(22*12)), "")))),0) -> 10 | U34: =IF(R34="Y",IF(O34="D",M34*N34,IF(O34="W",M34*(N34/5),IF(O34="M",M34*(N34/22),IF(O34="Y",M34*(N34/(22*12)), "")))),0) -> 10
A35: P | B35: 6 | C35: Maintain Team Supplies -Order from Libra | H35: TIS-00-0020 | I35: Order from Libra, purchase from Stores | M35: 5 | N35: 1 | O35: W | P35: Y | Q35: Y | R35: Y | S35: =IF(P35="Y",IF(O35="D",M35*N35,IF(O35="W",M35*(N35/5),IF(O35="M",M35*(N35/22),IF(O35="Y",M35*(N35/(22*12)), "")))),0) -> 1 | T35: =IF(Q35="Y",IF(O35="D",M35*N35,IF(O35="W",M35*(N35/5),IF(O35="M",M35*(N35/22),IF(O35="Y",M35*(N35/(22*12)), "")))),0) -> 1 | U35: =IF(R35="Y",IF(O35="D",M35*N35,IF(O35="W",M35*(N35/5),IF(O35="M",M35*(N35/22),IF(O35="Y",M35*(N35/(22*12)), "")))),0) -> 1
A36: P | B36: 7 | C36: Communicate information effectively and in a timely manner. | I36: Effective three-way communication. GL, TL & TM | M36: 3 | N36: 5 | O36: D | P36: Y | Q36: Y | R36: Y | S36: =IF(P36="Y",IF(O36="D",M36*N36,IF(O36="W",M36*(N36/5),IF(O36="M",M36*(N36/22),IF(O36="Y",M36*(N36/(22*12)), "")))),0) -> 15 | T36: =IF(Q36="Y",IF(O36="D",M36*N36,IF(O36="W",M36*(N36/5),IF(O36="M",M36*(N36/22),IF(O36="Y",M36*(N36/(22*12)), "")))),0) -> 15 | U36: =IF(R36="Y",IF(O36="D",M36*N36,IF(O36="W",M36*(N36/5),IF(O36="M",M36*(N36/22),IF(O36="Y",M36*(N36/(22*12)), "")))),0) -> 15
A37: P | B37: 8 | C37: Train Operator using JIT Process - update Flex | H37: TIS-00-0023 | I37: The purpose of JIT is to produce a professionally trained Team Member! | M37: 440 | N37: 1 | O37: M | P37: Y | Q37: Y | R37: Y | S37: =IF(P37="Y",IF(O37="D",M37*N37,IF(O37="W",M37*(N37/5),IF(O37="M",M37*(N37/22),IF(O37="Y",M37*(N37/(22*12)), "")))),0) -> 20 | T37: =IF(Q37="Y",IF(O37="D",M37*N37,IF(O37="W",M37*(N37/5),IF(O37="M",M37*(N37/22),IF(O37="Y",M37*(N37/(22*12)), "")))),0) -> 20 | U37: =IF(R37="Y",IF(O37="D",M37*N37,IF(O37="W",M37*(N37/5),IF(O37="M",M37*(N37/22),IF(O37="Y",M37*(N37/(22*12)), "")))),0) -> 20
A38: P | B38: 9 | C38: Maintain JESs and standardized work documents - ensure up to date | I38: Follow SW change process | M38: 25 | N38: 1 | O38: D | P38: Y | Q38: Y | R38: Y | S38: =IF(P38="Y",IF(O38="D",M38*N38,IF(O38="W",M38*(N38/5),IF(O38="M",M38*(N38/22),IF(O38="Y",M38*(N38/(22*12)), "")))),0) -> 25 | T38: =IF(Q38="Y",IF(O38="D",M38*N38,IF(O38="W",M38*(N38/5),IF(O38="M",M38*(N38/22),IF(O38="Y",M38*(N38/(22*12)), "")))),0) -> 25 | U38: =IF(R38="Y",IF(O38="D",M38*N38,IF(O38="W",M38*(N38/5),IF(O38="M",M38*(N38/22),IF(O38="Y",M38*(N38/(22*12)), "")))),0) -> 25
A39: P | B39: 10 | C39: Prepare for and lead Weekly Team Meetings | H39: TIS-00-0019 | I39: Follow SPQRCE and keep minutes | M39: 40 | N39: 1 | O39: W | P39: Y | Q39: Y | R39: Y | S39: =IF(P39="Y",IF(O39="D",M39*N39,IF(O39="W",M39*(N39/5),IF(O39="M",M39*(N39/22),IF(O39="Y",M39*(N39/(22*12)), "")))),0) -> 8 | T39: =IF(Q39="Y",IF(O39="D",M39*N39,IF(O39="W",M39*(N39/5),IF(O39="M",M39*(N39/22),IF(O39="Y",M39*(N39/(22*12)), "")))),0) -> 8 | U39: =IF(R39="Y",IF(O39="D",M39*N39,IF(O39="W",M39*(N39/5),IF(O39="M",M39*(N39/22),IF(O39="Y",M39*(N39/(22*12)), "")))),0) -> 8
A40: P | B40: 11 | C40: Support Team Members (respond to Andon calls, parts issues, etc.) | I40: Review data for improvement ideas | M40: 10 | N40: 8 | O40: D | P40: Y | Q40: Y | R40: Y | S40: =IF(P40="Y",IF(O40="D",M40*N40,IF(O40="W",M40*(N40/5),IF(O40="M",M40*(N40/22),IF(O40="Y",M40*(N40/(22*12)), "")))),0) -> 80 | T40: =IF(Q40="Y",IF(O40="D",M40*N40,IF(O40="W",M40*(N40/5),IF(O40="M",M40*(N40/22),IF(O40="Y",M40*(N40/(22*12)), "")))),0) -> 80 | U40: =IF(R40="Y",IF(O40="D",M40*N40,IF(O40="W",M40*(N40/5),IF(O40="M",M40*(N40/22),IF(O40="Y",M40*(N40/(22*12)), "")))),0) -> 80
A41: Q | B41: 12 | C41: Respond to radio calls, contact maintenance and make repairs as required. | I41: Get support from adjacent team leaders as needed. | M41: 10 | N41: 4 | O41: D | P41: Y | Q41: Y | R41: Y | S41: =IF(P41="Y",IF(O41="D",M41*N41,IF(O41="W",M41*(N41/5),IF(O41="M",M41*(N41/22),IF(O41="Y",M41*(N41/(22*12)), "")))),0) -> 40 | T41: =IF(Q41="Y",IF(O41="D",M41*N41,IF(O41="W",M41*(N41/5),IF(O41="M",M41*(N41/22),IF(O41="Y",M41*(N41/(22*12)), "")))),0) -> 40 | U41: =IF(R41="Y",IF(O41="D",M41*N41,IF(O41="W",M41*(N41/5),IF(O41="M",M41*(N41/22),IF(O41="Y",M41*(N41/(22*12)), "")))),0) -> 40
...

Sheet J1-Page2
A1: Plant Name: | C1: Wentzville | E1: STANDARD TASK SHEET | AB1: Available Op Time | AC1: Frequency | AD1: Shift Conditional | AF1: SPQRCE
A2: Department / Area: | F2: Available Operating Time: | I2: Prepared By: | AB2: 440 minutes (8 hours) | AC2: D | AD2: Y | AF2: S
A3: Trim - IP GLASS | F3: 440 minutes (8 hours) | I3: R. Woodson | AB3: 456 minutes (8 hours) | AC3: W | AD3: N | AF3: P
A4: Operation Name: | F4: Team: | I4: Page: | J4: Date: | AB4: 516 minutes(9 hours) | AC4: M | AF4: Q
A5: Team Leader | F5: J1 | I5: 2 of 2 | J5: 46114 | AB5: 576 minutes (10 hours) | AC5: Y | AF5: R
A6: STS Base Line Knowledge/Training: | AF6: C
AF7: E
A8: SAFETY | B8: All Required Safety Training (inc. Haz Material) | F8: QUALITY | G8: Process Control Plans | J8: COST | K8: Point Of Use, Spare Parts and Warranty
B9: High Risk TIS's/ Take 2 | G9: Quality Alerts | K9: COMMWIP - Waste Elimination
B10: Safety Playbook and Safety Policy | G10: Product Quality Standards | K10: Basic Ind. Material/Purchasing/SAP
B11: Emergency Response Process | G11: BIQ Process: Level III/IV | K11: Scrap Process
B12: SOT, SIR, ESCP, SOP, PPE, Ergonomics | G12: Problem Solving/Continuous Improvement
B13: Pre Task Planning/ Pre-Op card process | G13: Understanding PFMEA and MFMEA
A14: PEOPLE | B14: Computer Skills-E-mail, Microsoft Office, etc. | G14: GSIP | J14: ENVIRONMENTAL | K14: Understand E Requirements of the area
B15: TM/TL Evaluation Process | G15: Shop Floor Quality Systems - FBFF | K15: Work Place Organization (5-S)
B16: 4 Quarter Certified in all Team Jobs | G16: ISO | K16: Environmental Aspects / TISs
B17: Suggestions | F17: RESP. | G17: PM&C
B18: JIT Training & Flexibility Chart Training | G18: TIP (OEE and Constraints Management)
B19: GMS Training | G19: Maximo (CMMS)
B20: Layered Audits | G20: Andon and Plant Escalation Process
B21: Leading Effective Meetings | G21: Material Delivery System
B22: Team Concept, TM & TL R&Rs | G22: Total Productive Maintenance (TPM) | J22: SPQRCE | K22: JES/SOS/TIS (Safety/People/Responsiveness)
B23: TL STS and TISs | K23: BPD and Level 5 (SPQRCE)
B24: Plant Recognition Process | K24: Standardized Work (JES/SOS/TIS)
B25: Coaching Skills to help TMs improve
B26: Complete Proficiency Check Lists-3/4 Harvey
A28: SPQRCE | B28: # | C28: Task: | H28: TIS: | I28: Notes: | M28: Task Cycle Time: (Min.) | N28: Frequency: (Time) I (D=Day, W=Week, M=Month, Y=Year) | P28: Shift | S28: Total Cycle Time: (Daily) SHIFT
P29: 1 | Q29: 2 | R29: 3 | S29: 1 | T29: 2 | U29: 3
A30: E | B30: 31 | C30: Promote and monitor Waste Segregation with TMs | I30: Check trash, recycle, and glove containers regularly / coach TMs. | M30: 5 | N30: 1 | O30: D | P30: Y | Q30: Y | R30: Y | S30: =IF(P30="Y",IF(O30="D",M30*N30,IF(O30="W",M30*(N30/5),IF(O30="M",M30*(N30/22),IF(O30="Y",M30*(N30/(22*12)), "")))),0) -> 5 | T30: =IF(Q30="Y",IF(O30="D",M30*N30,IF(O30="W",M30*(N30/5),IF(O30="M",M30*(N30/22),IF(O30="Y",M30*(N30/(22*12)), "")))),0) -> 5 | U30: =IF(R30="Y",IF(O30="D",M30*N30,IF(O30="W",M30*(N30/5),IF(O30="M",M30*(N30/22),IF(O30="Y",M30*(N30/(22*12)), "")))),0) -> 5
A31: Q | B31: 32 | C31: Yellow Bag Process | I31: Ensure 100% clicking/beaming of fastners occurs until Torque Monitor verifies 3 good torque readings | M31: 15 | N31: 1 | O31: W | P31: N | Q31: N | R31: Y | S31: =IF(P31="Y",IF(O31="D",M31*N31,IF(O31="W",M31*(N31/5),IF(O31="M",M31*(N31/22),IF(O31="Y",M31*(N31/(22*12)), "")))),0) -> 0 | T31: =IF(Q31="Y",IF(O31="D",M31*N31,IF(O31="W",M31*(N31/5),IF(O31="M",M31*(N31/22),IF(O31="Y",M31*(N31/(22*12)), "")))),0) -> 0 | U31: =IF(R31="Y",IF(O31="D",M31*N31,IF(O31="W",M31*(N31/5),IF(O31="M",M31*(N31/22),IF(O31="Y",M31*(N31/(22*12)), "")))),0) -> 3
A32: Q | B32: 33 | C32: Blue Bag Process | I32: Ensure 100% clicking/beaming of fastners occurs until UAT is complete | M32: 3 | N32: 1 | O32: W | P32: Y | Q32: Y | R32: Y | S32: =IF(P32="Y",IF(O32="D",M32*N32,IF(O32="W",M32*(N32/5),IF(O32="M",M32*(N32/22),IF(O32="Y",M32*(N32/(22*12)), "")))),0) -> 0.6 | T32: =IF(Q32="Y",IF(O32="D",M32*N32,IF(O32="W",M32*(N32/5),IF(O32="M",M32*(N32/22),IF(O32="Y",M32*(N32/(22*12)), "")))),0) -> 0.6 | U32: =IF(R32="Y",IF(O32="D",M32*N32,IF(O32="W",M32*(N32/5),IF(O32="M",M32*(N32/22),IF(O32="Y",M32*(N32/(22*12)), "")))),0) -> 0.6
S33: =IF(P33="Y",IF(O33="D",M33*N33,IF(O33="W",M33*(N33/5),IF(O33="M",M33*(N33/22),IF(O33="Y",M33*(N33/(22*12)), "")))),0) -> 0 | T33: =IF(Q33="Y",IF(O33="D",M33*N33,IF(O33="W",M33*(N33/5),IF(O33="M",M33*(N33/22),IF(O33="Y",M33*(N33/(22*12)), "")))),0) -> 0 | U33: =IF(R33="Y",IF(O33="D",M33*N33,IF(O33="W",M33*(N33/5),IF(O33="M",M33*(N33/22),IF(O33="Y",M33*(N33/(22*12)), "")))),0) -> 0
S34: =IF(P34="Y",IF(O34="D",M34*N34,IF(O34="W",M34*(N34/5),IF(O34="M",M34*(N34/22),IF(O34="Y",M34*(N34/(22*12)), "")))),0) -> 0 | T34: =IF(Q34="Y",IF(O34="D",M34*N34,IF(O34="W",M34*(N34/5),IF(O34="M",M34*(N34/22),IF(O34="Y",M34*(N34/(22*12)), "")))),0) -> 0 | U34: =IF(R34="Y",IF(O34="D",M34*N34,IF(O34="W",M34*(N34/5),IF(O34="M",M34*(N34/22),IF(O34="Y",M34*(N34/(22*12)), "")))),0) -> 0
S35: =IF(P35="Y",IF(O35="D",M35*N35,IF(O35="W",M35*(N35/5),IF(O35="M",M35*(N35/22),IF(O35="Y",M35*(N35/(22*12)), "")))),0) -> 0 | T35: =IF(Q35="Y",IF(O35="D",M35*N35,IF(O35="W",M35*(N35/5),IF(O35="M",M35*(N35/22),IF(O35="Y",M35*(N35/(22*12)), "")))),0) -> 0 | U35: =IF(R35="Y",IF(O35="D",M35*N35,IF(O35="W",M35*(N35/5),IF(O35="M",M35*(N35/22),IF(O35="Y",M35*(N35/(22*12)), "")))),0) -> 0
S36: =IF(P36="Y",IF(O36="D",M36*N36,IF(O36="W",M36*(N36/5),IF(O36="M",M36*(N36/22),IF(O36="Y",M36*(N36/(22*12)), "")))),0) -> 0 | T36: =IF(Q36="Y",IF(O36="D",M36*N36,IF(O36="W",M36*(N36/5),IF(O36="M",M36*(N36/22),IF(O36="Y",M36*(N36/(22*12)), "")))),0) -> 0 | U36: =IF(R36="Y",IF(O36="D",M36*N36,IF(O36="W",M36*(N36/5),IF(O36="M",M36*(N36/22),IF(O36="Y",M36*(N36/(22*12)), "")))),0) -> 0
S37: =IF(P37="Y",IF(O37="D",M37*N37,IF(O37="W",M37*(N37/5),IF(O37="M",M37*(N37/22),IF(O37="Y",M37*(N37/(22*12)), "")))),0) -> 0 | T37: =IF(Q37="Y",IF(O37="D",M37*N37,IF(O37="W",M37*(N37/5),IF(O37="M",M37*(N37/22),IF(O37="Y",M37*(N37/(22*12)), "")))),0) -> 0 | U37: =IF(R37="Y",IF(O37="D",M37*N37,IF(O37="W",M37*(N37/5),IF(O37="M",M37*(N37/22),IF(O37="Y",M37*(N37/(22*12)), "")))),0) -> 0
S38: =IF(P38="Y",IF(O38="D",M38*N38,IF(O38="W",M38*(N38/5),IF(O38="M",M38*(N38/22),IF(O38="Y",M38*(N38/(22*12)), "")))),0) -> 0 | T38: =IF(Q38="Y",IF(O38="D",M38*N38,IF(O38="W",M38*(N38/5),IF(O38="M",M38*(N38/22),IF(O38="Y",M38*(N38/(22*12)), "")))),0) -> 0 | U38: =IF(R38="Y",IF(O38="D",M38*N38,IF(O38="W",M38*(N38/5),IF(O38="M",M38*(N38/22),IF(O38="Y",M38*(N38/(22*12)), "")))),0) -> 0
S39: =IF(P39="Y",IF(O39="D",M39*N39,IF(O39="W",M39*(N39/5),IF(O39="M",M39*(N39/22),IF(O39="Y",M39*(N39/(22*12)), "")))),0) -> 0 | T39: =IF(Q39="Y",IF(O39="D",M39*N39,IF(O39="W",M39*(N39/5),IF(O39="M",M39*(N39/22),IF(O39="Y",M39*(N39/(22*12)), "")))),0) -> 0 | U39: =IF(R39="Y",IF(O39="D",M39*N39,IF(O39="W",M39*(N39/5),IF(O39="M",M39*(N39/22),IF(O39="Y",M39*(N39/(22*12)), "")))),0) -> 0
S40: =IF(P40="Y",IF(O40="D",M40*N40,IF(O40="W",M40*(N40/5),IF(O40="M",M40*(N40/22),IF(O40="Y",M40*(N40/(22*12)), "")))),0) -> 0 | T40: =IF(Q40="Y",IF(O40="D",M40*N40,IF(O40="W",M40*(N40/5),IF(O40="M",M40*(N40/22),IF(O40="Y",M40*(N40/(22*12)), "")))),0) -> 0 | U40: =IF(R40="Y",IF(O40="D",M40*N40,IF(O40="W",M40*(N40/5),IF(O40="M",M40*(N40/22),IF(O40="Y",M40*(N40/(22*12)), "")))),0) -> 0
S41: =IF(P41="Y",IF(O41="D",M41*N41,IF(O41="W",M41*(N41/5),IF(O41="M",M41*(N41/22),IF(O41="Y",M41*(N41/(22*12)), "")))),0) -> 0 | T41: =IF(Q41="Y",IF(O41="D",M41*N41,IF(O41="W",M41*(N41/5),IF(O41="M",M41*(N41/22),IF(O41="Y",M41*(N41/(22*12)), "")))),0) -> 0 | U41: =IF(R41="Y",IF(O41="D",M41*N41,IF(O41="W",M41*(N41/5),IF(O41="M",M41*(N41/22),IF(O41="Y",M41*(N41/(22*12)), "")))),0) -> 0
...

Sheet STS Example
A1: Plant Name: | C1: Wentzville | E1: STANDARD TASK SHEET | AB1: Available Op Time | AC1: Frequency | AD1: Shift Conditional | AF1: SPQRCE
A2: Department / Area: | F2: Available Operating Time: | I2: Prepared By: | AB2: 440 minutes (8 hours) | AC2: D | AD2: Y | AF2: S
A3: Trim - Carpet | F3: 440 minutes (8 hours) | I3: Elwyn Employee | AB3: 456 minutes (8 hours) | AC3: W | AD3: N | AF3: P
A4: Operation Name: | F4: Team: | I4: Page: | J4: Date: | AB4: 516 minutes(9 hours) | AC4: M | AF4: Q
A5: H3 - Team Leader | F5: H3 | I5: 1 of 1 | J5: 45384 | AB5: 576 minutes (10 hours) | AC5: Y | AF5: R
A6: STS Base Line Knowledge/Training: | G6: GA Team Leader | AF6: C
AF7: E
A8: SAFETY | B8: All Required Safety Training (inc. Haz Material) | F8: QUALITY | G8: Process Control Plans | J8: COST | K8: Point Of Use, Spare Parts and Warranty
B9: High Risk TIS's/ Take 2 | G9: Quality Alerts | K9: COMMWIP - Waste Elimination
B10: Safety Playbook and Safety Policy | G10: Product Quality Standards | K10: Basic Ind. Material/Purchasing/SAP
B11: Emergency Response Process | G11: BIQ Process: Level III/IV | K11: Scrap Process
B12: SOT, SIR, ESCP, SOP, PPE, Ergonomics | G12: Problem Solving/Continuous Improvement
B13: Pre Task Planning/ Pre-Op card process | G13: Understanding PFMEA and MFMEA
A14: PEOPLE | B14: Computer Skills-E-mail, Microsoft Office, etc. | G14: GSIP | J14: ENVIRONMENTAL | K14: Understand E Requirements of the area
B15: TM/TL Evaluation Process | G15: Shop Floor Quality Systems - FBFF | K15: Work Place Organization (5-S)
B16: 4 Quarter Certified in all Team Jobs | G16: ISO | K16: Environmental Aspects / TISs
B17: Suggestions | F17: RESP. | G17: PM&C
B18: JIT Training & Flexibility Chart Training | G18: TIP (OEE and Constraints Management)
B19: GMS Training | G19: Maximo (CMMS)
B20: Layered Audits | G20: Andon and Plant Escalation Process
B21: Leading Effective Meetings | G21: Material Delivery System
B22: Team Concept, TM & TL R&Rs | G22: Total Productive Maintenance (TPM) | J22: SPQRCE | K22: JES/SOS/TIS (Safety/People/Responsiveness)
B23: TL STS and TISs | K23: BPD and Level 5 (SPQRCE)
B24: Plant Recognition Process | K24: Standardized Work (JES/SOS/TIS)
B25: Coaching Skills to help TMs improve
B26: Complete Proficiency Check Lists-3/4 Harvey
A28: SPQRCE | B28: # | C28: Task: | H28: TIS: | I28: Notes: | M28: Task Cycle Time: (Min.) | N28: Frequency: (Time) I (D=Day, W=Week, M=Month, Y=Year) | P28: Shift | S28: Total Cycle Time: (Daily) SHIFT
P29: 1 | Q29: 2 | R29: 3 | S29: 1 | T29: 2 | U29: 3
A30: P | B30: 1 | C30: Put out new PMP sheets for the week | I30: Print and place PMP sheets | M30: 5 | N30: 1 | O30: W | P30: N | Q30: N | R30: Y | S30: =IF(P30="Y",IF(O30="D",M30*N30,IF(O30="W",M30*(N30/5),IF(O30="M",M30*(N30/22),IF(O30="Y",M30*(N30/(22*12)), "")))),0) -> 0 | T30: =IF(Q30="Y",IF(O30="D",M30*N30,IF(O30="W",M30*(N30/5),IF(O30="M",M30*(N30/22),IF(O30="Y",M30*(N30/(22*12)), "")))),0) -> 0 | U30: =IF(R30="Y",IF(O30="D",M30*N30,IF(O30="W",M30*(N30/5),IF(O30="M",M30*(N30/22),IF(O30="Y",M30*(N30/(22*12)), "")))),0) -> 1
A31: R | B31: 2 | C31: Perform Start of shift activities | H31: 25-0001 | M31: 15 | N31: 1 | O31: D | P31: Y | Q31: Y | R31: Y | S31: =IF(P31="Y",IF(O31="D",M31*N31,IF(O31="W",M31*(N31/5),IF(O31="M",M31*(N31/22),IF(O31="Y",M31*(N31/(22*12)), "")))),0) -> 15 | T31: =IF(Q31="Y",IF(O31="D",M31*N31,IF(O31="W",M31*(N31/5),IF(O31="M",M31*(N31/22),IF(O31="Y",M31*(N31/(22*12)), "")))),0) -> 15 | U31: =IF(R31="Y",IF(O31="D",M31*N31,IF(O31="W",M31*(N31/5),IF(O31="M",M31*(N31/22),IF(O31="Y",M31*(N31/(22*12)), "")))),0) -> 15
A32: P | B32: 3 | C32: Collect prior week PMP sheets | I32: Collect and file paperwork | M32: 5 | N32: 1 | O32: W | P32: N | Q32: Y | R32: N | S32: =IF(P32="Y",IF(O32="D",M32*N32,IF(O32="W",M32*(N32/5),IF(O32="M",M32*(N32/22),IF(O32="Y",M32*(N32/(22*12)), "")))),0) -> 0 | T32: =IF(Q32="Y",IF(O32="D",M32*N32,IF(O32="W",M32*(N32/5),IF(O32="M",M32*(N32/22),IF(O32="Y",M32*(N32/(22*12)), "")))),0) -> 1 | U32: =IF(R32="Y",IF(O32="D",M32*N32,IF(O32="W",M32*(N32/5),IF(O32="M",M32*(N32/22),IF(O32="Y",M32*(N32/(22*12)), "")))),0) -> 0
A33: R | B33: 4 | C33: Attend weekly Standardization Basketweave Meeting | I33: Attend meeting, report info to team | M33: 45 | N33: 1 | O33: W | P33: Y | Q33: N | R33: N | S33: =IF(P33="Y",IF(O33="D",M33*N33,IF(O33="W",M33*(N33/5),IF(O33="M",M33*(N33/22),IF(O33="Y",M33*(N33/(22*12)), "")))),0) -> 9 | T33: =IF(Q33="Y",IF(O33="D",M33*N33,IF(O33="W",M33*(N33/5),IF(O33="M",M33*(N33/22),IF(O33="Y",M33*(N33/(22*12)), "")))),0) -> 0 | U33: =IF(R33="Y",IF(O33="D",M33*N33,IF(O33="W",M33*(N33/5),IF(O33="M",M33*(N33/22),IF(O33="Y",M33*(N33/(22*12)), "")))),0) -> 0
A34: R | B34: 5 | C34: Support Model Mix Variation | I34: Support TMs to accomplish operations in cycle | M34: 20 | N34: 1 | O34: D | P34: Y | Q34: Y | R34: Y | S34: =IF(P34="Y",IF(O34="D",M34*N34,IF(O34="W",M34*(N34/5),IF(O34="M",M34*(N34/22),IF(O34="Y",M34*(N34/(22*12)), "")))),0) -> 20 | T34: =IF(Q34="Y",IF(O34="D",M34*N34,IF(O34="W",M34*(N34/5),IF(O34="M",M34*(N34/22),IF(O34="Y",M34*(N34/(22*12)), "")))),0) -> 20 | U34: =IF(R34="Y",IF(O34="D",M34*N34,IF(O34="W",M34*(N34/5),IF(O34="M",M34*(N34/22),IF(O34="Y",M34*(N34/(22*12)), "")))),0) -> 20
A35: S | B35: 6 | C35: Perform PPE check in area | I35: Ensure TMs using proper PPE | M35: 5 | N35: 3 | O35: D | P35: Y | Q35: Y | R35: Y | S35: =IF(P35="Y",IF(O35="D",M35*N35,IF(O35="W",M35*(N35/5),IF(O35="M",M35*(N35/22),IF(O35="Y",M35*(N35/(22*12)), "")))),0) -> 15 | T35: =IF(Q35="Y",IF(O35="D",M35*N35,IF(O35="W",M35*(N35/5),IF(O35="M",M35*(N35/22),IF(O35="Y",M35*(N35/(22*12)), "")))),0) -> 15 | U35: =IF(R35="Y",IF(O35="D",M35*N35,IF(O35="W",M35*(N35/5),IF(O35="M",M35*(N35/22),IF(O35="Y",M35*(N35/(22*12)), "")))),0) -> 15
A36: S | B36: 7 | S36: =IF(P36="Y",IF(O36="D",M36*N36,IF(O36="W",M36*(N36/5),IF(O36="M",M36*(N36/22),IF(O36="Y",M36*(N36/(22*12)), "")))),0) -> 0 | T36: =IF(Q36="Y",IF(O36="D",M36*N36,IF(O36="W",M36*(N36/5),IF(O36="M",M36*(N36/22),IF(O36="Y",M36*(N36/(22*12)), "")))),0) -> 0 | U36: =IF(R36="Y",IF(O36="D",M36*N36,IF(O36="W",M36*(N36/5),IF(O36="M",M36*(N36/22),IF(O36="Y",M36*(N36/(22*12)), "")))),0) -> 0
A37: S | B37: 8 | S37: =IF(P37="Y",IF(O37="D",M37*N37,IF(O37="W",M37*(N37/5),IF(O37="M",M37*(N37/22),IF(O37="Y",M37*(N37/(22*12)), "")))),0) -> 0 | T37: =IF(Q37="Y",IF(O37="D",M37*N37,IF(O37="W",M37*(N37/5),IF(O37="M",M37*(N37/22),IF(O37="Y",M37*(N37/(22*12)), "")))),0) -> 0 | U37: =IF(R37="Y",IF(O37="D",M37*N37,IF(O37="W",M37*(N37/5),IF(O37="M",M37*(N37/22),IF(O37="Y",M37*(N37/(22*12)), "")))),0) -> 0
A38: P | B38: 9 | S38: =IF(P38="Y",IF(O38="D",M38*N38,IF(O38="W",M38*(N38/5),IF(O38="M",M38*(N38/22),IF(O38="Y",M38*(N38/(22*12)), "")))),0) -> 0 | T38: =IF(Q38="Y",IF(O38="D",M38*N38,IF(O38="W",M38*(N38/5),IF(O38="M",M38*(N38/22),IF(O38="Y",M38*(N38/(22*12)), "")))),0) -> 0 | U38: =IF(R38="Y",IF(O38="D",M38*N38,IF(O38="W",M38*(N38/5),IF(O38="M",M38*(N38/22),IF(O38="Y",M38*(N38/(22*12)), "")))),0) -> 0
A39: P | B39: 10 | S39: =IF(P39="Y",IF(O39="D",M39*N39,IF(O39="W",M39*(N39/5),IF(O39="M",M39*(N39/22),IF(O39="Y",M39*(N39/(22*12)), "")))),0) -> 0 | T39: =IF(Q39="Y",IF(O39="D",M39*N39,IF(O39="W",M39*(N39/5),IF(O39="M",M39*(N39/22),IF(O39="Y",M39*(N39/(22*12)), "")))),0) -> 0 | U39: =IF(R39="Y",IF(O39="D",M39*N39,IF(O39="W",M39*(N39/5),IF(O39="M",M39*(N39/22),IF(O39="Y",M39*(N39/(22*12)), "")))),0) -> 0
A40: P | B40: 11 | S40: =IF(P40="Y",IF(O40="D",M40*N40,IF(O40="W",M40*(N40/5),IF(O40="M",M40*(N40/22),IF(O40="Y",M40*(N40/(22*12)), "")))),0) -> 0 | T40: =IF(Q40="Y",IF(O40="D",M40*N40,IF(O40="W",M40*(N40/5),IF(O40="M",M40*(N40/22),IF(O40="Y",M40*(N40/(22*12)), "")))),0) -> 0 | U40: =IF(R40="Y",IF(O40="D",M40*N40,IF(O40="W",M40*(N40/5),IF(O40="M",M40*(N40/22),IF(O40="Y",M40*(N40/(22*12)), "")))),0) -> 0
A41: P | B41: 12 | S41: =IF(P41="Y",IF(O41="D",M41*N41,IF(O41="W",M41*(N41/5),IF(O41="M",M41*(N41/22),IF(O41="Y",M41*(N41/(22*12)), "")))),0) -> 0 | T41: =IF(Q41="Y",IF(O41="D",M41*N41,IF(O41="W",M41*(N41/5),IF(O41="M",M41*(N41/22),IF(O41="Y",M41*(N41/(22*12)), "")))),0) -> 0 | U41: =IF(R41="Y",IF(O41="D",M41*N41,IF(O41="W",M41*(N41/5),IF(O41="M",M41*(N41/22),IF(O41="Y",M41*(N41/(22*12)), "")))),0) -> 0
...

Sheet STS Audit
